<?xml version="1.0"?>
<!--  ==========================================================================================  -->
<!--  |    This document was autogenerated by scene_to_spawner from sailboat.xacro             |  -->
<!--  |    EDITING THIS FILE BY HAND IS NOT RECOMMENDED                                        |  -->
<!--  ==========================================================================================  -->
<robot xmlns:xacro="http://www.ros.org/wiki/xacro" name="sailboat">
  <link name="base_link">
    <visual>
      <origin rpy="0 0 0" xyz="0 0 0"/>
      <geometry>
        <mesh filename="meshes/simpleHull3/base_link.obj" scale="0.3 0.3 0.3"/>
      </geometry>
    </visual>
    </link>
  <link name="center_r_link">
    <visual>
      <origin rpy="0 0 0" xyz="0 0 0.0"/>
      <geometry>
        <mesh filename="meshes/simpleHull3/centerRight.obj" scale="0.3 0.3 0.3"/>
      </geometry>
    </visual>
    </link>
  <joint name="center_r_joint" type="revolute">
    <parent link="base_link"/>
    <child link="center_r_link"/>
    <origin rpy="0 0 0" xyz="0 0 0"/>
    <limit effort="50" lower="0" upper="0" velocity="5"/>
    <dynamics damping="1.0"/>
    <axis xyz="1 0 0"/>
  </joint>
  <link name="back_l_link">
    <visual>
      <origin rpy="0 0 0" xyz="0 0 0"/>
      <geometry>
        <mesh filename="meshes/simpleHull3/backLeft.obj" scale="0.3 0.3 0.3"/>
      </geometry>
    </visual>
    </link>
  <joint name="back_l_joint" type="revolute">
    <parent link="base_link"/>
    <child link="back_l_link"/>
    <origin rpy="0 0 0" xyz="-0.15 0.117 0"/>
    <limit effort="50" lower="0" upper="0" velocity="5"/>
    <dynamics damping="1.0"/>
    <axis xyz="1 0 0"/>
  </joint>
  <link name="back_r_link">
    <visual>
      <origin rpy="0 0 0" xyz="0 0 0"/>
      <geometry>
        <mesh filename="meshes/simpleHull3/backRight.obj" scale="0.3 0.3 0.3"/>
      </geometry>
    </visual>
    </link>
  <joint name="back_r_joint" type="revolute">
    <parent link="base_link"/>
    <child link="back_r_link"/>
    <origin rpy="0 0 0" xyz="-0.15 -0.117 0"/>
    <limit effort="50" lower="0" upper="0" velocity="5"/>
    <dynamics damping="1.0"/>
    <axis xyz="1 0 0"/>
  </joint>
  <link name="front_l_link">
    <visual>
      <origin rpy="0 0 0" xyz="0 0 0"/>
      <geometry>
        <mesh filename="meshes/simpleHull3/frontLeft.obj" scale="0.3 0.3 0.3"/>
      </geometry>
    </visual>
    </link>
  <joint name="front_l_joint" type="revolute">
    <parent link="base_link"/>
    <child link="front_l_link"/>
    <origin rpy="0 0 0" xyz="0.39 0.06 0"/>
    <limit effort="50" lower="0" upper="0" velocity="5"/>
    <dynamics damping="1.0"/>
    <axis xyz="1 0 0"/>
  </joint>
  <link name="front_r_link">
    <visual>
      <origin rpy="0 0 0" xyz="0 0 0"/>
      <geometry>
        <mesh filename="meshes/simpleHull3/frontRight.obj" scale="0.3 0.3 0.3"/>
      </geometry>
    </visual>
    </link>
  <joint name="front_r_joint" type="revolute">
    <parent link="base_link"/>
    <child link="front_r_link"/>
    <origin rpy="0 0 0" xyz="0.39 -0.06 0"/>
    <limit effort="50" lower="0" upper="0" velocity="5"/>
    <dynamics damping="1.0"/>
    <axis xyz="1 0 0"/>
  </joint>
  <joint name="hokuyo_joint" type="fixed">
    <axis xyz="0 1 0"/>
    <origin rpy="0 0 0" xyz="0.7 0 0.2"/>
    <parent link="base_link"/>
    <child link="hokuyo_link"/>
  </joint>
  <link name="hokuyo_link">
    <visual name="visual">
      <origin rpy="0 0 0" xyz="0 0 0"/>
      <geometry>
        <mesh filename="meshes/simpleHull3/box.obj" scale="0.1 0.1 0.1"/>
      </geometry>
    </visual>
    </link>
  <link name="rudder">
    <visual name="visual">
      <geometry>
        <mesh filename="meshes/simpleHull3/box.obj" scale="0.06 0.006 0.09"/>
      </geometry>
      <origin rpy="0 0 0" xyz="-0.03 0 0"/>
    </visual>
  </link>
  <joint name="rudder_joint" type="revolute">
    <parent link="back_r_link"/>
    <child link="rudder"/>
    <origin rpy="0 0 0" xyz="-0.42 0.117 -0.15"/>
    <dynamics damping="1.0"/>
    <axis xyz="0 0 1"/>
    <limit effort="100" lower="-1.57079632679" upper="1.57079632679" velocity="5"/>
  </joint>
  <link name="sail">
    <visual name="visual">
      <geometry>
        <mesh filename="meshes/simpleHull3/wingsail2.obj" scale="0.1 0.1 0.1"/>
      </geometry>
      <origin rpy="0 0 0" xyz="0 0 0"/>
    </visual>
  </link>
  <joint name="sail_joint" type="revolute">
    <parent link="base_link"/>
    <child link="sail"/>
    <origin rpy="0 0 0" xyz="0.2 0 0.1"/>
    <dynamics damping="1.0"/>
    <axis xyz="0 0 1"/>
    <limit effort="100" lower="-3.14159265359" upper="3.14159265359" velocity="70"/>
  </joint>
  <link name="keel">
    <visual name="visual">
      <geometry>
        <mesh filename="meshes/simpleHull3/box.obj" scale="0.25 0.02 0.5"/>
      </geometry>
      <origin rpy="0 0 0" xyz="0 0 0"/>
    </visual>
  </link>
  <joint name="keel_joint" type="revolute">
    <parent link="base_link"/>
    <child link="keel"/>
    <origin rpy="0 0 0" xyz="0 0 -0.35"/>
    <dynamics damping="1.0"/>
    <axis xyz="0 0 1"/>
    <limit effort="30" lower="0" upper="0" velocity="5"/>
  </joint>
  </robot>
